async/await 구문은 Promise 객체를 우리에게 이미 익숙한 동기 실행 코드 방식으로 다룰 수 있게 해주는 문법

```js
async function fetchPrint() {
  const resp = await fetch("https://jsonplaceholder.typicode.com/users");
  const result = await resp.text();
  console.log(result);
}
```

### async (asynchronous)
비동기: 함수 안에 비동기로 실행될 부분이 있음 (함수의 코드 중 promise 객체를 return하는 코드가 있다 / **함수 바깥의 코드들이 진행되고 난 후에 실행될 코드들이 있다**->await이 붙은 코드)
async는 항상 promise 객체를 return

1. 값 return
1-1. promise 객체 return
async안에서 promise 객체가 return-> async는 promise 객체와 동일한  promise 객체를 return
1-2. promise 객체 외의 값 rerturn
fulfilled 상태이면서, 리턴된 값을 작업 성공 결과로 가진 promise 객체를 return
2. 아무값도 return하지 않을 때
fulfilled 상태이면서, undefined를 작업 성공 결과로 가진 promise 객체를 return
3. async 함수 내부에서 error 발생
reject 상태이면서,  에러 객체를 작업 실패 정보로 가진 promise 객체를 return

#### async 함수 안의 async 
async 안에서는 다른 async 함수를 사용할 수 있음.
```js
async function f1(){}

async function f2(){
	const a = await f1;
}
```
이런식으로 앞에 await을 붙여서 다른 async함수 사용 가능 (async가 promise 객체를 return하기때문에 가능)

### await 
async 함수 안에서 사용
await 뒤의 코드를 실행하고 그 코드가 return하는 promise객체의 상태가 fullfilled/reject 상태가 될 때까지 기다림 -> 해당 작업이 완료 되어야 다음 코드를 실행
-fullfilled: 작업 성공 결과를 추출해서 return

await함수의 진행
```js
async function fetchPrint() {
  console.log(2);
  const resp = await fetch("https://jsonplaceholder.typicode.com/users");  // 1
  console.log(7);
  const result = await resp.text(); // 2
  console.log(result);
}

console.log(1);
fetchPrint();
console.log(3);
console.log(4);
console.log(5);
console.log(6);
```
위 코드의 진행은 await 1 뒤의 코드를 실행하고 fetchPrint 함수를 호출한 곳으로 가게 됨 -> 실행 흐름이 fetchPrint함수 바깥으로 -> 바깥의 코드가 다 실행되면 await 1 뒤의 promise객체의 상태가 fullfilled상태가 될 때까지 기다림(이미 fullfilled 상태일 수도) -> 작업 성공 결과를 추출해서 return -> 다음 코드 실행 -> await 2 뒤의 코드 실행 -> 실행 흐름이 fetchPrint함수 바깥으로 ->(그 아래 코드는 이미 await 1에서 다 실행했기때문에 추가로 실행x)-> await 2 뒤의 promise객체(text메소드가 return한)의 상태가 fullfilled상태가 될 때까지 기다림(이미 fullfilled 상태일 수도) -> 작업 결과가 result에 할당되고 그 내용이 출력
-await을 만나는 순간 함수 바깥의 코드를 실행하고 돌아옴 (**코드가 나열된 순서대로 진행되지 않는다**)

#### try...catch / finally
await 뒤의 코드가 return하는 promise객체가 reject 상태인 경우 => async/await에선 try...catch 사용 , 

```js
async function fetchPrint() {
  try {
    const resp = await fetch("https://jsonplaceholder.typicode.com/users");
    const result = await resp.text();
    console.log(result);
  } catch (error) {
    console.log(error);
  } finally {
    console.log('exit');
  }
}

fetchPrint();
```
cf)  promise객체가 reject 상태인 경우 catch 메소드 사용
